2025-10-19 14:48:27,411 DEBUG    root            Loaded Command Group: ['gcloud', 'services']
2025-10-19 14:48:27,551 DEBUG    root            Loaded Command Group: ['gcloud', 'services', 'list']
2025-10-19 14:48:27,554 DEBUG    root            Running [gcloud.services.list] with arguments: [--enabled: "True", --filter: "NAME=dataproc.googleapis.com", --project: "gentle-presence-472611-u8"]
2025-10-19 14:48:27,728 DEBUG    root            Chosen display Format:
          table(
            config.name:label=NAME:sort=1,
            config.title
          )
        
2025-10-19 14:48:27,730 INFO     root            Display format: "
          table(
            config.name:label=NAME:sort=1,
            config.title
          )
        "
2025-10-19 14:48:27,734 DEBUG    urllib3.connectionpool Starting new HTTPS connection (1): serviceusage.googleapis.com:443
2025-10-19 14:48:27,856 DEBUG    urllib3.connectionpool https://serviceusage.googleapis.com:443 "GET /v1/projects/gentle-presence-472611-u8/services?alt=json&filter=state%3AENABLED&pageSize=200 HTTP/11" 403 None
2025-10-19 14:48:27,862 DEBUG    root            Chosen display Format:default
2025-10-19 14:48:27,916 DEBUG    root            Chosen display Format:default
2025-10-19 14:48:27,918 DEBUG    root            Chosen display Format:default
2025-10-19 14:48:27,920 DEBUG    root            (gcloud.services.list) [66118017706-compute@developer.gserviceaccount.com] does not have permission to access projects instance [gentle-presence-472611-u8] (or it may not exist): Permission denied to list services for consumer container [projects/66118017706]
Help Token: AVSZLmtD_IbkdgRkQT1d3Uotm6w9-O0MYpk6lkcxWNTmQFaxS6KGkC4IipvrABWRsLfVW_r_McDFOLLtCidgQbV5bG56Ogq9kbmrQYMKf19-WiTk. This command is authenticated as 66118017706-compute@developer.gserviceaccount.com which is the active account specified by the [core/account] property
- '@type': type.googleapis.com/google.rpc.PreconditionFailure
  violations:
  - subject: '110002'
    type: googleapis.com
- '@type': type.googleapis.com/google.rpc.ErrorInfo
  domain: serviceusage.googleapis.com
  reason: AUTH_PERMISSION_DENIED
Traceback (most recent call last):
  File "/usr/bin/../lib/google-cloud-sdk/lib/googlecloudsdk/calliope/cli.py", line 944, in Execute
    resources = calliope_command.Run(cli=self, args=args)
                ^^^^^^^^^^^^^^^^^^^^^^^^^^^^^^^^^^^^^^^^^
  File "/usr/bin/../lib/google-cloud-sdk/lib/googlecloudsdk/calliope/backend.py", line 958, in Run
    ).Display()
      ^^^^^^^^^
  File "/usr/bin/../lib/google-cloud-sdk/lib/googlecloudsdk/calliope/display.py", line 507, in Display
    self._printer.Print(self._resources)
  File "/usr/bin/../lib/google-cloud-sdk/lib/googlecloudsdk/core/resource/resource_printer_base.py", line 301, in Print
    for resource in resources:
                    ^^^^^^^^^
  File "/usr/bin/../lib/google-cloud-sdk/lib/googlecloudsdk/core/util/peek_iterable.py", line 211, in __next__
    item = self._NextItem()
           ^^^^^^^^^^^^^^^^
  File "/usr/bin/../lib/google-cloud-sdk/lib/googlecloudsdk/core/util/peek_iterable.py", line 183, in _NextItem
    return next(self._iterable)
           ^^^^^^^^^^^^^^^^^^^^
  File "/usr/bin/../lib/google-cloud-sdk/lib/googlecloudsdk/core/util/peek_iterable.py", line 211, in __next__
    item = self._NextItem()
           ^^^^^^^^^^^^^^^^
  File "/usr/bin/../lib/google-cloud-sdk/lib/googlecloudsdk/core/util/peek_iterable.py", line 183, in _NextItem
    return next(self._iterable)
           ^^^^^^^^^^^^^^^^^^^^
  File "/usr/bin/../lib/google-cloud-sdk/lib/third_party/apitools/base/py/list_pager.py", line 120, in YieldFromList
    response = getattr(service, method)(request,
               ^^^^^^^^^^^^^^^^^^^^^^^^^^^^^^^^^
  File "/usr/bin/../lib/google-cloud-sdk/lib/googlecloudsdk/api_lib/util/http_retry.py", line 41, in wrapper
    return retryer.RetryOnException(func, args, kwargs,
           ^^^^^^^^^^^^^^^^^^^^^^^^^^^^^^^^^^^^^^^^^^^^
  File "/usr/bin/../lib/google-cloud-sdk/lib/googlecloudsdk/core/util/retry.py", line 201, in RetryOnException
    exceptions.reraise(exc_info[1], tb=exc_info[2])
  File "/usr/bin/../lib/google-cloud-sdk/lib/googlecloudsdk/core/exceptions.py", line 149, in reraise
    six.reraise(type(exc_value), exc_value, tb)
  File "/usr/bin/../lib/google-cloud-sdk/lib/third_party/six/__init__.py", line 719, in reraise
    raise value
  File "/usr/bin/../lib/google-cloud-sdk/lib/googlecloudsdk/core/util/retry.py", line 182, in TryFunc
    return func(*args, **kwargs), None
           ^^^^^^^^^^^^^^^^^^^^^
  File "/usr/bin/../lib/google-cloud-sdk/lib/googlecloudsdk/api_lib/services/serviceusage.py", line 1173, in List
    return self.service_usage.List(request, global_params=global_params)
           ^^^^^^^^^^^^^^^^^^^^^^^^^^^^^^^^^^^^^^^^^^^^^^^^^^^^^^^^^^^^^
  File "/usr/bin/../lib/google-cloud-sdk/lib/googlecloudsdk/generated_clients/apis/serviceusage/v1/serviceusage_v1_client.py", line 317, in List
    return self._RunMethod(
           ^^^^^^^^^^^^^^^^
  File "/usr/bin/../lib/google-cloud-sdk/lib/third_party/apitools/base/py/base_api.py", line 747, in _RunMethod
    return self.ProcessHttpResponse(method_config, http_response, request)
           ^^^^^^^^^^^^^^^^^^^^^^^^^^^^^^^^^^^^^^^^^^^^^^^^^^^^^^^^^^^^^^^
  File "/usr/bin/../lib/google-cloud-sdk/lib/third_party/apitools/base/py/base_api.py", line 753, in ProcessHttpResponse
    self.__ProcessHttpResponse(method_config, http_response, request))
    ^^^^^^^^^^^^^^^^^^^^^^^^^^^^^^^^^^^^^^^^^^^^^^^^^^^^^^^^^^^^^^^^^
  File "/usr/bin/../lib/google-cloud-sdk/lib/third_party/apitools/base/py/base_api.py", line 612, in __ProcessHttpResponse
    raise exceptions.HttpError.FromResponse(
apitools.base.py.exceptions.HttpForbiddenError: HttpError accessing <https://serviceusage.googleapis.com/v1/projects/gentle-presence-472611-u8/services?alt=json&filter=state%3AENABLED&pageSize=200>: response: <{'vary': 'Origin, X-Origin, Referer', 'content-type': 'application/json; charset=UTF-8', 'content-encoding': 'gzip', 'date': 'Sun, 19 Oct 2025 14:48:28 GMT', 'server': 'ESF', 'x-xss-protection': '0', 'x-frame-options': 'SAMEORIGIN', 'x-content-type-options': 'nosniff', 'transfer-encoding': 'chunked', 'status': 403}>, content <{
  "error": {
    "code": 403,
    "message": "Permission denied to list services for consumer container [projects/66118017706]\nHelp Token: AVSZLmtD_IbkdgRkQT1d3Uotm6w9-O0MYpk6lkcxWNTmQFaxS6KGkC4IipvrABWRsLfVW_r_McDFOLLtCidgQbV5bG56Ogq9kbmrQYMKf19-WiTk",
    "status": "PERMISSION_DENIED",
    "details": [
      {
        "@type": "type.googleapis.com/google.rpc.PreconditionFailure",
        "violations": [
          {
            "type": "googleapis.com",
            "subject": "110002"
          }
        ]
      },
      {
        "@type": "type.googleapis.com/google.rpc.ErrorInfo",
        "reason": "AUTH_PERMISSION_DENIED",
        "domain": "serviceusage.googleapis.com"
      }
    ]
  }
}
>
2025-10-19 14:48:28,070 ERROR    root            (gcloud.services.list) [66118017706-compute@developer.gserviceaccount.com] does not have permission to access projects instance [gentle-presence-472611-u8] (or it may not exist): Permission denied to list services for consumer container [projects/66118017706]
Help Token: AVSZLmtD_IbkdgRkQT1d3Uotm6w9-O0MYpk6lkcxWNTmQFaxS6KGkC4IipvrABWRsLfVW_r_McDFOLLtCidgQbV5bG56Ogq9kbmrQYMKf19-WiTk. This command is authenticated as 66118017706-compute@developer.gserviceaccount.com which is the active account specified by the [core/account] property
- '@type': type.googleapis.com/google.rpc.PreconditionFailure
  violations:
  - subject: '110002'
    type: googleapis.com
- '@type': type.googleapis.com/google.rpc.ErrorInfo
  domain: serviceusage.googleapis.com
  reason: AUTH_PERMISSION_DENIED
